<?xml version="1.0" ?>
<!-- =================================================================================== -->
<!-- |    This document was autogenerated by xacro from /root/catkin_ws/src/motoman/motoman_motomini_support/urdf/motomini.xacro | -->
<!-- |    EDITING THIS FILE BY HAND IS NOT RECOMMENDED                                 | -->
<!-- =================================================================================== -->
<robot name="motoman_motomini">
    <!-- link list -->
    <link name="world" />
    <link name="base_link">
        <visual>
            <geometry>
                <mesh filename="package://motoman_motomini_support/meshes/motomini/visual/base_link.stl" />
            </geometry>
            <material name="">
                <color rgba="0.12941176470588237 0.14901960784313725 0.7490196078431373 1.0" />
            </material>
        </visual>
        <collision>
            <geometry>
                <mesh filename="package://motoman_motomini_support/meshes/motomini/collision/base_link.stl" />
            </geometry>
        </collision>
        <inertial>
            <mass value="0.1" />
            <origin xyz="0 0 0" rpy="0 0 0" />
            <inertia ixx="0.03" iyy="0.03" izz="0.03" ixy="0.0" ixz="0.0" iyz="0.0" />
        </inertial>
    </link>
    <link name="link_1_s">
        <visual>
            <geometry>
                <mesh filename="package://motoman_motomini_support/meshes/motomini/visual/link_1_s.stl" />
            </geometry>
            <material name="">
                <color rgba="0.12941176470588237 0.14901960784313725 0.7490196078431373 1.0" />
            </material>
        </visual>
        <collision>
            <geometry>
                <mesh filename="package://motoman_motomini_support/meshes/motomini/collision/link_1_s.stl" />
            </geometry>
        </collision>
        <inertial>
            <mass value="0.1" />
            <origin xyz="0 0 0" rpy="0 0 0" />
            <inertia ixx="0.03" iyy="0.03" izz="0.03" ixy="0.0" ixz="0.0" iyz="0.0" />
        </inertial>
    </link>
    <link name="link_2_l">
        <visual>
            <geometry>
                <mesh filename="package://motoman_motomini_support/meshes/motomini/visual/link_2_l.stl" />
            </geometry>
            <material name="">
                <color rgba="0.12941176470588237 0.14901960784313725 0.7490196078431373 1.0" />
            </material>
        </visual>
        <collision>
            <geometry>
                <mesh filename="package://motoman_motomini_support/meshes/motomini/collision/link_2_l.stl" />
            </geometry>
        </collision>
        <inertial>
            <mass value="0.1" />
            <origin xyz="0 0 0" rpy="0 0 0" />
            <inertia ixx="0.03" iyy="0.03" izz="0.03" ixy="0.0" ixz="0.0" iyz="0.0" />
        </inertial>
    </link>
    <link name="link_3_u">
        <visual>
            <geometry>
                <mesh filename="package://motoman_motomini_support/meshes/motomini/visual/link_3_u.stl" />
            </geometry>
            <material name="">
                <color rgba="0.12941176470588237 0.14901960784313725 0.7490196078431373 1.0" />
            </material>
        </visual>
        <collision>
            <geometry>
                <mesh filename="package://motoman_motomini_support/meshes/motomini/collision/link_3_u.stl" />
            </geometry>
        </collision>
        <inertial>
            <mass value="0.1" />
            <origin xyz="0 0 0" rpy="0 0 0" />
            <inertia ixx="0.03" iyy="0.03" izz="0.03" ixy="0.0" ixz="0.0" iyz="0.0" />
        </inertial>
    </link>
    <link name="link_4_r">
        <visual>
            <geometry>
                <mesh filename="package://motoman_motomini_support/meshes/motomini/visual/link_4_r.stl" />
            </geometry>
            <material name="">
                <color rgba="0.12941176470588237 0.14901960784313725 0.7490196078431373 1.0" />
            </material>
        </visual>
        <collision>
            <geometry>
                <mesh filename="package://motoman_motomini_support/meshes/motomini/collision/link_4_r.stl" />
            </geometry>
        </collision>
        <inertial>
            <mass value="0.1" />
            <origin xyz="0 0 0" rpy="0 0 0" />
            <inertia ixx="0.03" iyy="0.03" izz="0.03" ixy="0.0" ixz="0.0" iyz="0.0" />
        </inertial>
    </link>
    <link name="link_5_b">
        <visual>
            <geometry>
                <mesh filename="package://motoman_motomini_support/meshes/motomini/visual/link_5_b.stl" />
            </geometry>
            <material name="">
                <color rgba="0.12941176470588237 0.14901960784313725 0.7490196078431373 1.0" />
            </material>
        </visual>
        <collision>
            <geometry>
                <mesh filename="package://motoman_motomini_support/meshes/motomini/collision/link_5_b.stl" />
            </geometry>
        </collision>
        <inertial>
            <mass value="0.1" />
            <origin xyz="0 0 0" rpy="0 0 0" />
            <inertia ixx="0.03" iyy="0.03" izz="0.03" ixy="0.0" ixz="0.0" iyz="0.0" />
        </inertial>
    </link>
    <link name="link_6_t">
        <visual>
            <geometry>
                <mesh filename="package://motoman_motomini_support/meshes/motomini/visual/link_6_t.stl" />
            </geometry>
            <material name="">
                <color rgba="0.12941176470588237 0.14901960784313725 0.7490196078431373 1.0" />
            </material>
        </visual>
        <collision>
            <geometry>
                <mesh filename="package://motoman_motomini_support/meshes/motomini/collision/link_6_t.stl" />
            </geometry>
        </collision>
        <inertial>
            <mass value="0.1" />
            <origin xyz="0 0 0" rpy="0 0 0" />
            <inertia ixx="0.03" iyy="0.03" izz="0.03" ixy="0.0" ixz="0.0" iyz="0.0" />
        </inertial>
    </link>
    <link name="tool0" />
    <!-- end of link list -->
    <!-- joint list -->
    <joint name="world_joint" type="fixed">
        <parent link="world" />
        <child link="base_link" />
        <origin rpy="0 0 0" xyz="0 0 0" />
    </joint>
    <joint name="joint_1_s" type="revolute">
        <parent link="base_link" />
        <child link="link_1_s" />
        <origin rpy="0 0 0" xyz="0 0 0.103" />
        <axis xyz="0 0 1" />
        <limit effort="0.12" lower="-2.9670" upper="2.9670" velocity="5.4977" />
    </joint>
    <joint name="joint_2_l" type="revolute">
        <parent link="link_1_s" />
        <child link="link_2_l" />
        <origin rpy="0 0 0" xyz="0.020 0 0" />
        <axis xyz="0 1 0" />
        <limit effort="0.12" lower="-1.4835" upper="1.5707" velocity="5.4977" />
    </joint>
    <joint name="joint_3_u" type="revolute">
        <parent link="link_2_l" />
        <child link="link_3_u" />
        <origin rpy="0 0 0" xyz="0 0 0.165" />
        <axis xyz="0 -1 0" />
        <limit effort="0.12" lower="-0.8726" upper="1.5707" velocity="7.3304" />
    </joint>
    <joint name="joint_4_r" type="revolute">
        <parent link="link_3_u" />
        <child link="link_4_r" />
        <origin rpy="0 0 0" xyz="0.165 0 0" />
        <axis xyz="-1 0 0" />
        <limit effort="0.07" lower="-2.4434" upper="2.4434" velocity="10.4719" />
    </joint>
    <joint name="joint_5_b" type="revolute">
        <parent link="link_4_r" />
        <child link="link_5_b" />
        <origin rpy="0 0 0" xyz="0 0 0" />
        <axis xyz="0 -1 0" />
        <limit effort="0.07" lower="-0.5235" upper="3.6651" velocity="10.4719" />
    </joint>
    <joint name="joint_6_t" type="revolute">
        <parent link="link_5_b" />
        <child link="link_6_t" />
        <origin rpy="0 0 0" xyz="0 0 0" />
        <axis xyz="0 0 1" />
        <limit effort="0.07" lower="-6.2831" upper="6.2831" velocity="10.4719" />
    </joint>
    <joint name="joint_6_t-tool0" type="fixed">
        <origin rpy="3.141592653589793 0 0" xyz="0 0 -0.040 " />
        <parent link="link_6_t" />
        <child link="tool0" />
    </joint>
    <!-- end of joint list -->
    <!-- ROS base_link to Robot Manufacturer World Coordinates transform -->
    <link name="base" />
    <joint name="base_link-base" type="fixed">
        <origin rpy="0 0 0" xyz="0 0 0.103" />
        <parent link="base_link" />
        <child link="base" />
    </joint>
    <transmission name="trans_joint_1_s">
        <type>transmission_interface/SimpleTransmission</type>
        <joint name="joint_1_s">
            <hardwareInterface>hardware_interface/EffortJointInterface</hardwareInterface>
        </joint>
        <actuator name="joint_1_s_motor">
            <hardwareInterface>hardware_interface/EffortJointInterface</hardwareInterface>
            <mechanicalReduction>1</mechanicalReduction>
        </actuator>
    </transmission>
    <transmission name="trans_joint_2_l">
        <type>transmission_interface/SimpleTransmission</type>
        <joint name="joint_2_l">
            <hardwareInterface>hardware_interface/EffortJointInterface</hardwareInterface>
        </joint>
        <actuator name="joint_2_l_motor">
            <hardwareInterface>hardware_interface/EffortJointInterface</hardwareInterface>
            <mechanicalReduction>1</mechanicalReduction>
        </actuator>
    </transmission>
    <transmission name="trans_joint_3_u">
        <type>transmission_interface/SimpleTransmission</type>
        <joint name="joint_3_u">
            <hardwareInterface>hardware_interface/EffortJointInterface</hardwareInterface>
        </joint>
        <actuator name="joint_3_u_motor">
            <hardwareInterface>hardware_interface/EffortJointInterface</hardwareInterface>
            <mechanicalReduction>1</mechanicalReduction>
        </actuator>
    </transmission>
    <transmission name="trans_joint_4_r">
        <type>transmission_interface/SimpleTransmission</type>
        <joint name="joint_4_r">
            <hardwareInterface>hardware_interface/EffortJointInterface</hardwareInterface>
        </joint>
        <actuator name="joint_4_r_motor">
            <hardwareInterface>hardware_interface/EffortJointInterface</hardwareInterface>
            <mechanicalReduction>1</mechanicalReduction>
        </actuator>
    </transmission>
    <transmission name="trans_joint_5_b">
        <type>transmission_interface/SimpleTransmission</type>
        <joint name="joint_5_b">
            <hardwareInterface>hardware_interface/EffortJointInterface</hardwareInterface>
        </joint>
        <actuator name="joint_5_b_motor">
            <hardwareInterface>hardware_interface/EffortJointInterface</hardwareInterface>
            <mechanicalReduction>1</mechanicalReduction>
        </actuator>
    </transmission>
    <transmission name="trans_joint_6_t">
        <type>transmission_interface/SimpleTransmission</type>
        <joint name="joint_6_t">
            <hardwareInterface>hardware_interface/EffortJointInterface</hardwareInterface>
        </joint>
        <actuator name="joint_6_t_motor">
            <hardwareInterface>hardware_interface/EffortJointInterface</hardwareInterface>
            <mechanicalReduction>1</mechanicalReduction>
        </actuator>
    </transmission>
    <gazebo>
        <plugin name="gazebo_ros_control" filename="libgazebo_ros_control.so">
            <robotNamespace>/</robotNamespace>
        </plugin>
    </gazebo>
</robot>

